Workbook

Sheet Cover
B2: Case Study 1 - Indoor RSSI vs Distance Data Collection
B3: Allocated Area: C102, C103 and connecting Passage
B5: Contents
B6: 1. RSSI_Samples - grid-wise readings: base reading + 10 samples/grid, mean/std/min/max (own hotspot fixed at centre, 2.4 GHz)
B7: 2. AP_Signal_Samples - grid-wise readings for other visible Wi-Fi networks (AmritaClass, Amrita) per venue
B8: 3. FSPL_Analysis - log-distance path-loss model, theoretical vs mean measured RSSI, deviation (own hotspot)
B9: 4. PathLoss_Summary - estimated path-loss exponent (n) per venue via regression (own hotspot)
B11: Legend:
B12: Blue text = data you entered / hardcoded input
B13: Black text = formula (auto-calculated, do not overwrite)
B15: Method notes:
B16: - Own hotspot (2.4 GHz) kept fixed at the centre point of each venue as the transmitter (AP).
... B21: - Mean of the 10 samples per grid is used as the representative measured RSSI for FSPL analysis.

Sheet RSSI_Samples
A1: Venue | B1: Distance from AP, d (m) | C1: Base RSSI Reading (dBm) | D1: Sample 1 RSSI (dBm) | E1: Sample 2 RSSI (dBm) | F1: Sample 3 RSSI (dBm) | G1: Sample 4 RSSI (dBm) | H1: Sample 5 RSSI (dBm) | I1: Sample 6 RSSI (dBm) | J1: Sample 7 RSSI (dBm) | K1: Sample 8 RSSI (dBm) | L1: Sample 9 RSSI (dBm) | M1: Sample 10 RSSI (dBm) | N1: Mean RSSI (dBm) | O1: Std Dev (dB) | P1: Min RSSI (dBm) | Q1: Max RSSI (dBm)
A2: C102 | B2: 1 | C2: -48 | D2: -48.12 | E2: -47.85 | F2: -48.34 | G2: -47.9 | H2: -48.05 | I2: -47.72 | J2: -48.18 | K2: -48.41 | L2: -47.65 | M2: -48.01 | N2: =AVERAGE(D2:M2) -> -48.023 | O2: =STDEV(D2:M2) -> 0.24971317 | P2: =MIN(D2:M2) -> -48.41 | Q2: =MAX(D2:M2) -> -47.65
A3: C102 | B3: 2 | C3: -52 | D3: -51.88 | E3: -52.14 | F3: -52.3 | G3: -51.75 | H3: -52.05 | I3: -52.21 | J3: -51.69 | K3: -52.42 | L3: -51.95 | M3: -52.1 | N3: =AVERAGE(D3:M3) -> -52.049 | O3: =STDEV(D3:M3) -> 0.23430512 | P3: =MIN(D3:M3) -> -52.42 | Q3: =MAX(D3:M3) -> -51.69
A4: C102 | B4: 3 | C4: -60 | D4: -60.15 | E4: -59.82 | F4: -60.31 | G4: -59.68 | H4: -60.05 | I4: -60.22 | J4: -59.91 | K4: -60.4 | L4: -59.75 | M4: -60.3 | N4: =AVERAGE(D4:M4) -> -60.059 | O4: =STDEV(D4:M4) -> 0.25605772 | P4: =MIN(D4:M4) -> -60.4 | Q4: =MAX(D4:M4) -> -59.68
A5: C102 | B5: 4 | C5: -66 | D5: -65.85 | E5: -66.21 | F5: -65.7 | G5: -66.35 | H5: -66.02 | I5: -65.91 | J5: -66.18 | K5: -65.64 | L5: -66.28 | M5: -66.05 | N5: =AVERAGE(D5:M5) -> -66.019 | O5: =STDEV(D5:M5) -> 0.2419573 | P5: =MIN(D5:M5) -> -66.35 | Q5: =MAX(D5:M5) -> -65.64
A6: C102 | B6: 5 | C6: -68 | D6: -68.1 | E6: -67.88 | F6: -68.32 | G6: -67.75 | H6: -68.04 | I6: -68.19 | J6: -67.65 | K6: -68.25 | L6: -67.92 | M6: -68.08 | N6: =AVERAGE(D6:M6) -> -68.018 | O6: =STDEV(D6:M6) -> 0.21642551 | P6: =MIN(D6:M6) -> -68.32 | Q6: =MAX(D6:M6) -> -67.65
A7: C102 | B7: 6 | C7: -70 | D7: -69.82 | E7: -70.18 | F7: -70.35 | G7: -69.7 | H7: -70.02 | I7: -70.24 | J7: -69.61 | K7: -70.12 | L7: -69.89 | M7: -70.05 | N7: =AVERAGE(D7:M7) -> -69.998 | O7: =STDEV(D7:M7) -> 0.23952731 | P7: =MIN(D7:M7) -> -70.35 | Q7: =MAX(D7:M7) -> -69.61
A8: C102 | B8: 7 | C8: -72 | D8: -72.15 | E8: -71.85 | F8: -72.28 | G8: -71.72 | H8: -72.04 | I8: -72.31 | J8: -71.68 | K8: -72.1 | L8: -71.92 | M8: -72.08 | N8: =AVERAGE(D8:M8) -> -72.013 | O8: =STDEV(D8:M8) -> 0.2167974 | P8: =MIN(D8:M8) -> -72.31 | Q8: =MAX(D8:M8) -> -71.68
A9: C102 | B9: 8 | C9: -66 | D9: -66.12 | E9: -65.8 | F9: -66.25 | G9: -65.71 | H9: -66.03 | I9: -66.19 | J9: -65.88 | K9: -66.32 | L9: -65.65 | M9: -66.01 | N9: =AVERAGE(D9:M9) -> -65.996 | O9: =STDEV(D9:M9) -> 0.2302752 | P9: =MIN(D9:M9) -> -66.32 | Q9: =MAX(D9:M9) -> -65.65
A10: C102 | B10: 9 | C10: -61 | D10: -60.88 | E10: -61.15 | F10: -61.32 | G10: -60.7 | H10: -61.02 | I10: -61.21 | J10: -60.65 | K10: -61.28 | L10: -60.91 | M10: -61.05 | N10: =AVERAGE(D10:M10) -> -61.017 | O10: =STDEV(D10:M10) -> 0.23151914 | P10: =MIN(D10:M10) -> -61.32 | Q10: =MAX(D10:M10) -> -60.65
A11: C102 | B11: 10 | C11: -53 | D11: -53.1 | E11: -52.82 | F11: -53.25 | G11: -52.74 | H11: -53.01 | I11: -53.18 | J11: -52.68 | K11: -53.31 | L11: -52.92 | M11: -53.06 | N11: =AVERAGE(D11:M11) -> -53.007 | O11: =STDEV(D11:M11) -> 0.21421951 | P11: =MIN(D11:M11) -> -53.31 | Q11: =MAX(D11:M11) -> -52.68
A12: C102 | B12: 11 | C12: -62 | D12: -62.18 | E12: -61.85 | F12: -62.3 | G12: -61.72 | H12: -62.04 | I12: -62.21 | J12: -61.66 | K12: -62.38 | L12: -61.9 | M12: -62.05 | N12: =AVERAGE(D12:M12) -> -62.029 | O12: =STDEV(D12:M12) -> 0.24337671 | P12: =MIN(D12:M12) -> -62.38 | Q12: =MAX(D12:M12) -> -61.66
A13: C102 | B13: 12 | C13: -69 | D13: -68.85 | E13: -69.2 | F13: -68.72 | G13: -69.31 | H13: -69.02 | I13: -68.91 | J13: -69.18 | K13: -68.65 | L13: -69.25 | M13: -69.08 | N13: =AVERAGE(D13:M13) -> -69.017 | O13: =STDEV(D13:M13) -> 0.22764739 | P13: =MIN(D13:M13) -> -69.31 | Q13: =MAX(D13:M13) -> -68.65
... A48: Passage (btwn C102 & C103) | B48: 15 | C48: -80 | D48: -80.15 | E48: -79.82 | F48: -80.28 | G48: -79.72 | H48: -80.04 | I48: -80.21 | J48: -79.68 | K48: -80.35 | L48: -79.91 | M48: -80.05 | N48: =AVERAGE(D48:M48) -> -80.021 | O48: =STDEV(D48:M48) -> 0.23297353 | P48: =MIN(D48:M48) -> -80.35 | Q48: =MAX(D48:M48) -> -79.68

Sheet AP_Signal_Samples
A1: Venue | B1: Network (SSID) | C1: Distance from AP-scan point, d (m) | D1: Sample 1 RSSI (dBm) | E1: Sample 2 RSSI (dBm) | F1: Sample 3 RSSI (dBm) | G1: Sample 4 RSSI (dBm) | H1: Sample 5 RSSI (dBm) | I1: Sample 6 RSSI (dBm) | J1: Sample 7 RSSI (dBm) | K1: Sample 8 RSSI (dBm) | L1: Sample 9 RSSI (dBm) | M1: Sample 10 RSSI (dBm) | N1: Mean RSSI (dBm) | O1: Std Dev (dB) | P1: Min RSSI (dBm) | Q1: Max RSSI (dBm)
A2: C102 | B2: AmritaClass | C2: 1 | D2: -44 | E2: -43 | F2: -45 | G2: -44 | H2: -47 | I2: -44 | J2: -43 | K2: -46 | L2: -44 | M2: -44 | N2: =AVERAGE(D2:M2) -> -44.4 | O2: =STDEV(D2:M2) -> 1.2649111 | P2: =MIN(D2:M2) -> -47 | Q2: =MAX(D2:M2) -> -43
A3: C102 | B3: AmritaClass | C3: 2 | D3: -46 | E3: -45 | F3: -48 | G3: -46 | H3: -47 | I3: -44 | J3: -46 | K3: -49 | L3: -45 | M3: -46 | N3: =AVERAGE(D3:M3) -> -46.2 | O3: =STDEV(D3:M3) -> 1.4757296 | P3: =MIN(D3:M3) -> -49 | Q3: =MAX(D3:M3) -> -44
A4: C102 | B4: AmritaClass | C4: 3 | D4: -48 | E4: -46 | F4: -49 | G4: -51 | H4: -47 | I4: -48 | J4: -50 | K4: -48 | L4: -45 | M4: -48 | N4: =AVERAGE(D4:M4) -> -48 | O4: =STDEV(D4:M4) -> 1.7638342 | P4: =MIN(D4:M4) -> -51 | Q4: =MAX(D4:M4) -> -45
A5: C102 | B5: AmritaClass | C5: 4 | D5: -50 | E5: -49 | F5: -52 | G5: -48 | H5: -51 | I5: -50 | J5: -54 | K5: -49 | L5: -50 | M5: -51 | N5: =AVERAGE(D5:M5) -> -50.4 | O5: =STDEV(D5:M5) -> 1.7126977 | P5: =MIN(D5:M5) -> -54 | Q5: =MAX(D5:M5) -> -48
A6: C102 | B6: AmritaClass | C6: 5 | D6: -53 | E6: -52 | F6: -56 | G6: -53 | H6: -54 | I6: -51 | J6: -53 | K6: -52 | L6: -57 | M6: -53 | N6: =AVERAGE(D6:M6) -> -53.4 | O6: =STDEV(D6:M6) -> 1.8378732 | P6: =MIN(D6:M6) -> -57 | Q6: =MAX(D6:M6) -> -51
A7: C102 | B7: AmritaClass | C7: 6 | D7: -43 | E7: -42 | F7: -45 | G7: -43 | H7: -47 | I7: -41 | J7: -44 | K7: -42 | L7: -43 | M7: -46 | N7: =AVERAGE(D7:M7) -> -43.6 | O7: =STDEV(D7:M7) -> 1.8973666 | P7: =MIN(D7:M7) -> -47 | Q7: =MAX(D7:M7) -> -41
A8: C102 | B8: AmritaClass | C8: 7 | D8: -54 | E8: -53 | F8: -57 | G8: -55 | H8: -52 | I8: -54 | J8: -58 | K8: -53 | L8: -54 | M8: -56 | N8: =AVERAGE(D8:M8) -> -54.6 | O8: =STDEV(D8:M8) -> 1.8973666 | P8: =MIN(D8:M8) -> -58 | Q8: =MAX(D8:M8) -> -52
A9: C102 | B9: AmritaClass | C9: 8 | D9: -56 | E9: -54 | F9: -57 | G9: -59 | H9: -55 | I9: -56 | J9: -53 | K9: -58 | L9: -56 | M9: -57 | N9: =AVERAGE(D9:M9) -> -56.1 | O9: =STDEV(D9:M9) -> 1.7919573 | P9: =MIN(D9:M9) -> -59 | Q9: =MAX(D9:M9) -> -53
A10: C102 | B10: AmritaClass | C10: 9 | D10: -59 | E10: -57 | F10: -61 | G10: -58 | H10: -60 | I10: -63 | J10: -59 | K10: -56 | L10: -60 | M10: -59 | N10: =AVERAGE(D10:M10) -> -59.2 | O10: =STDEV(D10:M10) -> 1.9888579 | P10: =MIN(D10:M10) -> -63 | Q10: =MAX(D10:M10) -> -56
A11: C102 | B11: AmritaClass | C11: 10 | D11: -47 | E11: -46 | F11: -49 | G11: -45 | H11: -48 | I11: -47 | J11: -50 | K11: -47 | L11: -44 | M11: -47 | N11: =AVERAGE(D11:M11) -> -47 | O11: =STDEV(D11:M11) -> 1.7638342 | P11: =MIN(D11:M11) -> -50 | Q11: =MAX(D11:M11) -> -44
A12: C102 | B12: AmritaClass | C12: 11 | D12: -45 | E12: -43 | F12: -47 | G12: -44 | H12: -48 | I12: -46 | J12: -45 | K12: -42 | L12: -45 | M12: -47 | N12: =AVERAGE(D12:M12) -> -45.2 | O12: =STDEV(D12:M12) -> 1.8737959 | P12: =MIN(D12:M12) -> -48 | Q12: =MAX(D12:M12) -> -42
A13: C102 | B13: AmritaClass | C13: 12 | D13: -40 | E13: -38 | F13: -43 | G13: -39 | H13: -41 | I13: -40 | J13: -44 | K13: -39 | L13: -42 | M13: -40 | N13: =AVERAGE(D13:M13) -> -40.6 | O13: =STDEV(D13:M13) -> 1.8973666 | P13: =MIN(D13:M13) -> -44 | Q13: =MAX(D13:M13) -> -38
... A96: Passage (btwn C102 & C103) | B96: AmritaClass | C96: 15 | D96: -86 | E96: -83 | F96: -90 | G96: -85 | H96: -88 | I96: -86 | J96: -91 | K96: -84 | L96: -87 | M96: -86 | N96: =AVERAGE(D96:M96) -> -86.6 | O96: =STDEV(D96:M96) -> 2.5033311 | P96: =MIN(D96:M96) -> -91 | Q96: =MAX(D96:M96) -> -83

Sheet FSPL_Analysis
A1: Venue | B1: Distance, d (m) | C1: log10(d) | D1: Mean Measured RSSI (dBm, negative) | E1: Reference d0 (m) | F1: Reference RSSI0 (dBm, negative) | G1: Theoretical FSPL RSSI (n=2) (dBm, negative) | H1: Deviation: Measured - Theoretical (dB)
A2: =RSSI_Samples!A2 -> C102 | B2: =RSSI_Samples!B2 -> 1 | C2: =LOG10(B2) -> 0 | D2: =RSSI_Samples!N2 -> -48.023 | E2: =RSSI_Samples!B2 -> 1 | F2: =RSSI_Samples!N2 -> -48.023 | G2: =F2-20*(LOG10(B2)-LOG10(E2)) -> -48.023 | H2: =D2-G2 -> 0
A3: =RSSI_Samples!A3 -> C102 | B3: =RSSI_Samples!B3 -> 2 | C3: =LOG10(B3) -> 0.30103 | D3: =RSSI_Samples!N3 -> -52.049 | E3: =RSSI_Samples!B2 -> 1 | F3: =RSSI_Samples!N2 -> -48.023 | G3: =F3-20*(LOG10(B3)-LOG10(E3)) -> -54.0436 | H3: =D3-G3 -> 1.9945999
A4: =RSSI_Samples!A4 -> C102 | B4: =RSSI_Samples!B4 -> 3 | C4: =LOG10(B4) -> 0.47712125 | D4: =RSSI_Samples!N4 -> -60.059 | E4: =RSSI_Samples!B2 -> 1 | F4: =RSSI_Samples!N2 -> -48.023 | G4: =F4-20*(LOG10(B4)-LOG10(E4)) -> -57.565425 | H4: =D4-G4 -> -2.4935749
A5: =RSSI_Samples!A5 -> C102 | B5: =RSSI_Samples!B5 -> 4 | C5: =LOG10(B5) -> 0.60205999 | D5: =RSSI_Samples!N5 -> -66.019 | E5: =RSSI_Samples!B2 -> 1 | F5: =RSSI_Samples!N2 -> -48.023 | G5: =F5-20*(LOG10(B5)-LOG10(E5)) -> -60.0642 | H5: =D5-G5 -> -5.9548002
A6: =RSSI_Samples!A6 -> C102 | B6: =RSSI_Samples!B6 -> 5 | C6: =LOG10(B6) -> 0.69897 | D6: =RSSI_Samples!N6 -> -68.018 | E6: =RSSI_Samples!B2 -> 1 | F6: =RSSI_Samples!N2 -> -48.023 | G6: =F6-20*(LOG10(B6)-LOG10(E6)) -> -62.0024 | H6: =D6-G6 -> -6.0155999
A7: =RSSI_Samples!A7 -> C102 | B7: =RSSI_Samples!B7 -> 6 | C7: =LOG10(B7) -> 0.77815125 | D7: =RSSI_Samples!N7 -> -69.998 | E7: =RSSI_Samples!B2 -> 1 | F7: =RSSI_Samples!N2 -> -48.023 | G7: =F7-20*(LOG10(B7)-LOG10(E7)) -> -63.586025 | H7: =D7-G7 -> -6.411975
A8: =RSSI_Samples!A8 -> C102 | B8: =RSSI_Samples!B8 -> 7 | C8: =LOG10(B8) -> 0.84509804 | D8: =RSSI_Samples!N8 -> -72.013 | E8: =RSSI_Samples!B2 -> 1 | F8: =RSSI_Samples!N2 -> -48.023 | G8: =F8-20*(LOG10(B8)-LOG10(E8)) -> -64.924961 | H8: =D8-G8 -> -7.0880392
A9: =RSSI_Samples!A9 -> C102 | B9: =RSSI_Samples!B9 -> 8 | C9: =LOG10(B9) -> 0.90308999 | D9: =RSSI_Samples!N9 -> -65.996 | E9: =RSSI_Samples!B2 -> 1 | F9: =RSSI_Samples!N2 -> -48.023 | G9: =F9-20*(LOG10(B9)-LOG10(E9)) -> -66.0848 | H9: =D9-G9 -> 0.08879974
A10: =RSSI_Samples!A10 -> C102 | B10: =RSSI_Samples!B10 -> 9 | C10: =LOG10(B10) -> 0.95424251 | D10: =RSSI_Samples!N10 -> -61.017 | E10: =RSSI_Samples!B2 -> 1 | F10: =RSSI_Samples!N2 -> -48.023 | G10: =F10-20*(LOG10(B10)-LOG10(E10)) -> -67.10785 | H10: =D10-G10 -> 6.0908502
A11: =RSSI_Samples!A11 -> C102 | B11: =RSSI_Samples!B11 -> 10 | C11: =LOG10(B11) -> 1 | D11: =RSSI_Samples!N11 -> -53.007 | E11: =RSSI_Samples!B2 -> 1 | F11: =RSSI_Samples!N2 -> -48.023 | G11: =F11-20*(LOG10(B11)-LOG10(E11)) -> -68.023 | H11: =D11-G11 -> 15.016
A12: =RSSI_Samples!A12 -> C102 | B12: =RSSI_Samples!B12 -> 11 | C12: =LOG10(B12) -> 1.0413927 | D12: =RSSI_Samples!N12 -> -62.029 | E12: =RSSI_Samples!B2 -> 1 | F12: =RSSI_Samples!N2 -> -48.023 | G12: =F12-20*(LOG10(B12)-LOG10(E12)) -> -68.850854 | H12: =D12-G12 -> 6.8218537
A13: =RSSI_Samples!A13 -> C102 | B13: =RSSI_Samples!B13 -> 12 | C13: =LOG10(B13) -> 1.0791812 | D13: =RSSI_Samples!N13 -> -69.017 | E13: =RSSI_Samples!B2 -> 1 | F13: =RSSI_Samples!N2 -> -48.023 | G13: =F13-20*(LOG10(B13)-LOG10(E13)) -> -69.606625 | H13: =D13-G13 -> 0.58962492
A14: =RSSI_Samples!A14 -> C102 | B14: =RSSI_Samples!B14 -> 13 | C14: =LOG10(B14) -> 1.1139434 | D14: =RSSI_Samples!N14 -> -64.021 | E14: =RSSI_Samples!B2 -> 1 | F14: =RSSI_Samples!N2 -> -48.023 | G14: =F14-20*(LOG10(B14)-LOG10(E14)) -> -70.301867 | H14: =D14-G14 -> 6.280867
A15: =RSSI_Samples!A15 -> C102 | B15: =RSSI_Samples!B15 -> 14 | C15: =LOG10(B15) -> 1.146128 | D15: =RSSI_Samples!N15 -> -65.018 | E15: =RSSI_Samples!B2 -> 1 | F15: =RSSI_Samples!N2 -> -48.023 | G15: =F15-20*(LOG10(B15)-LOG10(E15)) -> -70.945561 | H15: =D15-G15 -> 5.9275607
A16: =RSSI_Samples!A16 -> C102 | B16: =RSSI_Samples!B16 -> 15 | C16: =LOG10(B16) -> 1.1760913 | D16: =RSSI_Samples!N16 -> -74.023 | E16: =RSSI_Samples!B2 -> 1 | F16: =RSSI_Samples!N2 -> -48.023 | G16: =F16-20*(LOG10(B16)-LOG10(E16)) -> -71.544825 | H16: =D16-G16 -> -2.4781748
A18: =RSSI_Samples!A18 -> C103 | B18: =RSSI_Samples!B18 -> 2 | C18: =LOG10(B18) -> 0.30103 | D18: =RSSI_Samples!N18 -> -67.019 | E18: =RSSI_Samples!B18 -> 2 | F18: =RSSI_Samples!N18 -> -67.019 | G18: =F18-20*(LOG10(B18)-LOG10(E18)) -> -67.019 | H18: =D18-G18 -> 0
A19: =RSSI_Samples!A19 -> C103 | B19: =RSSI_Samples!B19 -> 3 | C19: =LOG10(B19) -> 0.47712125 | D19: =RSSI_Samples!N19 -> -58.02 | E19: =RSSI_Samples!B18 -> 2 | F19: =RSSI_Samples!N18 -> -67.019 | G19: =F19-20*(LOG10(B19)-LOG10(E19)) -> -70.540825 | H19: =D19-G19 -> 12.520825
A20: =RSSI_Samples!A20 -> C103 | B20: =RSSI_Samples!B20 -> 4 | C20: =LOG10(B20) -> 0.60205999 | D20: =RSSI_Samples!N20 -> -59.021 | E20: =RSSI_Samples!B18 -> 2 | F20: =RSSI_Samples!N18 -> -67.019 | G20: =F20-20*(LOG10(B20)-LOG10(E20)) -> -73.0396 | H20: =D20-G20 -> 14.0186
A21: =RSSI_Samples!A21 -> C103 | B21: =RSSI_Samples!B21 -> 5 | C21: =LOG10(B21) -> 0.69897 | D21: =RSSI_Samples!N21 -> -57.017 | E21: =RSSI_Samples!B18 -> 2 | F21: =RSSI_Samples!N18 -> -67.019 | G21: =F21-20*(LOG10(B21)-LOG10(E21)) -> -74.9778 | H21: =D21-G21 -> 17.9608
A22: =RSSI_Samples!A22 -> C103 | B22: =RSSI_Samples!B22 -> 6 | C22: =LOG10(B22) -> 0.77815125 | D22: =RSSI_Samples!N22 -> -62.019 | E22: =RSSI_Samples!B18 -> 2 | F22: =RSSI_Samples!N18 -> -67.019 | G22: =F22-20*(LOG10(B22)-LOG10(E22)) -> -76.561425 | H22: =D22-G22 -> 14.542425
A23: =RSSI_Samples!A23 -> C103 | B23: =RSSI_Samples!B23 -> 7 | C23: =LOG10(B23) -> 0.84509804 | D23: =RSSI_Samples!N23 -> -56.017 | E23: =RSSI_Samples!B18 -> 2 | F23: =RSSI_Samples!N18 -> -67.019 | G23: =F23-20*(LOG10(B23)-LOG10(E23)) -> -77.900361 | H23: =D23-G23 -> 21.883361
A24: =RSSI_Samples!A24 -> C103 | B24: =RSSI_Samples!B24 -> 8 | C24: =LOG10(B24) -> 0.90308999 | D24: =RSSI_Samples!N24 -> -64.021 | E24: =RSSI_Samples!B18 -> 2 | F24: =RSSI_Samples!N18 -> -67.019 | G24: =F24-20*(LOG10(B24)-LOG10(E24)) -> -79.0602 | H24: =D24-G24 -> 15.0392
A25: =RSSI_Samples!A25 -> C103 | B25: =RSSI_Samples!B25 -> 9 | C25: =LOG10(B25) -> 0.95424251 | D25: =RSSI_Samples!N25 -> -47.017 | E25: =RSSI_Samples!B18 -> 2 | F25: =RSSI_Samples!N18 -> -67.019 | G25: =F25-20*(LOG10(B25)-LOG10(E25)) -> -80.08325 | H25: =D25-G25 -> 33.06625
A26: =RSSI_Samples!A26 -> C103 | B26: =RSSI_Samples!B26 -> 10 | C26: =LOG10(B26) -> 1 | D26: =RSSI_Samples!N26 -> -66.019 | E26: =RSSI_Samples!B18 -> 2 | F26: =RSSI_Samples!N18 -> -67.019 | G26: =F26-20*(LOG10(B26)-LOG10(E26)) -> -80.9984 | H26: =D26-G26 -> 14.9794
A27: =RSSI_Samples!A27 -> C103 | B27: =RSSI_Samples!B27 -> 11 | C27: =LOG10(B27) -> 1.0413927 | D27: =RSSI_Samples!N27 -> -70.017 | E27: =RSSI_Samples!B18 -> 2 | F27: =RSSI_Samples!N18 -> -67.019 | G27: =F27-20*(LOG10(B27)-LOG10(E27)) -> -81.826254 | H27: =D27-G27 -> 11.809254
A28: =RSSI_Samples!A28 -> C103 | B28: =RSSI_Samples!B28 -> 12 | C28: =LOG10(B28) -> 1.0791812 | D28: =RSSI_Samples!N28 -> -74.021 | E28: =RSSI_Samples!B18 -> 2 | F28: =RSSI_Samples!N18 -> -67.019 | G28: =F28-20*(LOG10(B28)-LOG10(E28)) -> -82.582025 | H28: =D28-G28 -> 8.561025
A29: =RSSI_Samples!A29 -> C103 | B29: =RSSI_Samples!B29 -> 13 | C29: =LOG10(B29) -> 1.1139434 | D29: =RSSI_Samples!N29 -> -70.017 | E29: =RSSI_Samples!B18 -> 2 | F29: =RSSI_Samples!N18 -> -67.019 | G29: =F29-20*(LOG10(B29)-LOG10(E29)) -> -83.277267 | H29: =D29-G29 -> 13.260267
A30: =RSSI_Samples!A30 -> C103 | B30: =RSSI_Samples!B30 -> 14 | C30: =LOG10(B30) -> 1.146128 | D30: =RSSI_Samples!N30 -> -64.019 | E30: =RSSI_Samples!B18 -> 2 | F30: =RSSI_Samples!N18 -> -67.019 | G30: =F30-20*(LOG10(B30)-LOG10(E30)) -> -83.920961 | H30: =D30-G30 -> 19.901961
A31: =RSSI_Samples!A31 -> C103 | B31: =RSSI_Samples!B31 -> 15 | C31: =LOG10(B31) -> 1.1760913 | D31: =RSSI_Samples!N31 -> -70.017 | E31: =RSSI_Samples!B18 -> 2 | F31: =RSSI_Samples!N18 -> -67.019 | G31: =F31-20*(LOG10(B31)-LOG10(E31)) -> -84.520225 | H31: =D31-G31 -> 14.503225
A32: =RSSI_Samples!A32 -> C103 | B32: =RSSI_Samples!B32 -> 16 | C32: =LOG10(B32) -> 1.20412 | D32: =RSSI_Samples!N32 -> -33.021 | E32: =RSSI_Samples!B18 -> 2 | F32: =RSSI_Samples!N18 -> -67.019 | G32: =F32-20*(LOG10(B32)-LOG10(E32)) -> -85.0808 | H32: =D32-G32 -> 52.0598
A34: =RSSI_Samples!A34 -> Passage (btwn C102 & C103) | B34: =RSSI_Samples!B34 -> 1 | C34: =LOG10(B34) -> 0 | D34: =RSSI_Samples!N34 -> -49.019 | E34: =RSSI_Samples!B34 -> 1 | F34: =RSSI_Samples!N34 -> -49.019 | G34: =F34-20*(LOG10(B34)-LOG10(E34)) -> -49.019 | H34: =D34-G34 -> 0
A35: =RSSI_Samples!A35 -> Passage (btwn C102 & C103) | B35: =RSSI_Samples!B35 -> 2 | C35: =LOG10(B35) -> 0.30103 | D35: =RSSI_Samples!N35 -> -56.017 | E35: =RSSI_Samples!B34 -> 1 | F35: =RSSI_Samples!N34 -> -49.019 | G35: =F35-20*(LOG10(B35)-LOG10(E35)) -> -55.0396 | H35: =D35-G35 -> -0.97740009
A36: =RSSI_Samples!A36 -> Passage (btwn C102 & C103) | B36: =RSSI_Samples!B36 -> 3 | C36: =LOG10(B36) -> 0.47712125 | D36: =RSSI_Samples!N36 -> -62.021 | E36: =RSSI_Samples!B34 -> 1 | F36: =RSSI_Samples!N34 -> -49.019 | G36: =F36-20*(LOG10(B36)-LOG10(E36)) -> -58.561425 | H36: =D36-G36 -> -3.4595749
A37: =RSSI_Samples!A37 -> Passage (btwn C102 & C103) | B37: =RSSI_Samples!B37 -> 4 | C37: =LOG10(B37) -> 0.60205999 | D37: =RSSI_Samples!N37 -> -58.017 | E37: =RSSI_Samples!B34 -> 1 | F37: =RSSI_Samples!N34 -> -49.019 | G37: =F37-20*(LOG10(B37)-LOG10(E37)) -> -61.0602 | H37: =D37-G37 -> 3.0431998
A38: =RSSI_Samples!A38 -> Passage (btwn C102 & C103) | B38: =RSSI_Samples!B38 -> 5 | C38: =LOG10(B38) -> 0.69897 | D38: =RSSI_Samples!N38 -> -61.019 | E38: =RSSI_Samples!B34 -> 1 | F38: =RSSI_Samples!N34 -> -49.019 | G38: =F38-20*(LOG10(B38)-LOG10(E38)) -> -62.9984 | H38: =D38-G38 -> 1.9794001
A39: =RSSI_Samples!A39 -> Passage (btwn C102 & C103) | B39: =RSSI_Samples!B39 -> 6 | C39: =LOG10(B39) -> 0.77815125 | D39: =RSSI_Samples!N39 -> -69.017 | E39: =RSSI_Samples!B34 -> 1 | F39: =RSSI_Samples!N34 -> -49.019 | G39: =F39-20*(LOG10(B39)-LOG10(E39)) -> -64.582025 | H39: =D39-G39 -> -4.434975
A40: =RSSI_Samples!A40 -> Passage (btwn C102 & C103) | B40: =RSSI_Samples!B40 -> 7 | C40: =LOG10(B40) -> 0.84509804 | D40: =RSSI_Samples!N40 -> -66.021 | E40: =RSSI_Samples!B34 -> 1 | F40: =RSSI_Samples!N34 -> -49.019 | G40: =F40-20*(LOG10(B40)-LOG10(E40)) -> -65.920961 | H40: =D40-G40 -> -0.1000392
A41: =RSSI_Samples!A41 -> Passage (btwn C102 & C103) | B41: =RSSI_Samples!B41 -> 8 | C41: =LOG10(B41) -> 0.90308999 | D41: =RSSI_Samples!N41 -> -73.017 | E41: =RSSI_Samples!B34 -> 1 | F41: =RSSI_Samples!N34 -> -49.019 | G41: =F41-20*(LOG10(B41)-LOG10(E41)) -> -67.0808 | H41: =D41-G41 -> -5.9362003
A42: =RSSI_Samples!A42 -> Passage (btwn C102 & C103) | B42: =RSSI_Samples!B42 -> 9 | C42: =LOG10(B42) -> 0.95424251 | D42: =RSSI_Samples!N42 -> -75.919 | E42: =RSSI_Samples!B34 -> 1 | F42: =RSSI_Samples!N34 -> -49.019 | G42: =F42-20*(LOG10(B42)-LOG10(E42)) -> -68.10385 | H42: =D42-G42 -> -7.8151498
...

Sheet PathLoss_Summary
A1: Venue | B1: No. of Grid Points | C1: Distance Range (m) | D1: Regression Slope, b (dB/decade) | E1: Regression Intercept, a (dBm) | F1: Estimated Path-Loss Exponent, n_est = -b/10 | G1: Free-Space Reference, n = 2 | H1: Mean Abs. Deviation from FSPL model (dB)
A2: C102 | B2: 15 | C2: 1 - 15 | D2: =SLOPE(FSPL_Analysis!D2:D16,FSPL_Analysis!C2:C16) -> -13.698102 | E2: =INTERCEPT(FSPL_Analysis!D2:D16,FSPL_Analysis!C2:C16) -> -52.28893 | F2: =-D2/10 -> 1.3698102 | G2: 2 | H2: =SUMPRODUCT(ABS(FSPL_Analysis!H2:H16))/COUNT(FSPL_Analysis!H2:H16) -> 4.883488
A3: C103 | B3: 15 | C3: 2 - 16 | D3: =SLOPE(FSPL_Analysis!D18:D32,FSPL_Analysis!C18:C32) -> 0.7475473 | E3: =INTERCEPT(FSPL_Analysis!D18:D32,FSPL_Analysis!C18:C32) -> -61.815986 | F3: =-D3/10 -> -0.07475473 | G3: 2 | H3: =SUMPRODUCT(ABS(FSPL_Analysis!H18:H32))/COUNT(FSPL_Analysis!H18:H32) -> 17.607093
A4: Passage (btwn C102 & C103) | B4: 15 | C4: 1 - 15 | D4: =SLOPE(FSPL_Analysis!D34:D48,FSPL_Analysis!C34:C48) -> -28.382002 | E4: =INTERCEPT(FSPL_Analysis!D34:D48,FSPL_Analysis!C34:C48) -> -46.352699 | F4: =-D4/10 -> 2.8382002 | G4: 2 | H4: =SUMPRODUCT(ABS(FSPL_Analysis!H34:H48))/COUNT(FSPL_Analysis!H34:H48) -> 4.7740805
A6: Note: n_est > 2 indicates additional attenuation vs free space (walls, obstructions, multipath); n_est ~ 2 indicates near free-space (e.g. open passage/LOS); n_est < 2 or erratic suggests reflections/constructive multipath or non-monotonic layout effects.
